[2023-04-29T15:34:56.886-0300] {taskinstance.py:1084} INFO - Dependencies all met for dep_context=non-requeueable deps ti=<TaskInstance: climate_dag.extract_data scheduled__2023-02-13T00:00:00+00:00 [queued]>
[2023-04-29T15:34:56.891-0300] {taskinstance.py:1084} INFO - Dependencies all met for dep_context=requeueable deps ti=<TaskInstance: climate_dag.extract_data scheduled__2023-02-13T00:00:00+00:00 [queued]>
[2023-04-29T15:34:56.891-0300] {taskinstance.py:1282} INFO - 
--------------------------------------------------------------------------------
[2023-04-29T15:34:56.891-0300] {taskinstance.py:1283} INFO - Starting attempt 1 of 1
[2023-04-29T15:34:56.891-0300] {taskinstance.py:1284} INFO - 
--------------------------------------------------------------------------------
[2023-04-29T15:34:56.900-0300] {taskinstance.py:1303} INFO - Executing <Task(PythonOperator): extract_data> on 2023-02-13 00:00:00+00:00
[2023-04-29T15:34:56.903-0300] {standard_task_runner.py:55} INFO - Started process 20584 to run task
[2023-04-29T15:34:56.906-0300] {standard_task_runner.py:82} INFO - Running: ['airflow', 'tasks', 'run', 'climate_dag', 'extract_data', 'scheduled__2023-02-13T00:00:00+00:00', '--job-id', '61', '--raw', '--subdir', 'DAGS_FOLDER/climate_data.py', '--cfg-path', '/tmp/tmpw3rr4vjj']
[2023-04-29T15:34:56.908-0300] {standard_task_runner.py:83} INFO - Job 61: Subtask extract_data
[2023-04-29T15:34:56.936-0300] {task_command.py:388} INFO - Running <TaskInstance: climate_dag.extract_data scheduled__2023-02-13T00:00:00+00:00 [running]> on host nicholas10-ThinkPad-E14-Gen-3
[2023-04-29T15:34:56.953-0300] {abstractoperator.py:611} ERROR - Exception rendering Jinja template for task 'extract_data', field 'op_kwargs'. Template: {'data_interval_end': '{{data_interval_end.strftime(%Y-%m-%d)}}'}
Traceback (most recent call last):
  File "/home/nicholas10/airflow/dataengvenv/lib/python3.10/site-packages/airflow/models/abstractoperator.py", line 603, in _do_render_template_fields
    rendered_content = self.render_template(
  File "/home/nicholas10/airflow/dataengvenv/lib/python3.10/site-packages/airflow/models/abstractoperator.py", line 678, in render_template
    return {k: self.render_template(v, context, jinja_env, oids) for k, v in value.items()}
  File "/home/nicholas10/airflow/dataengvenv/lib/python3.10/site-packages/airflow/models/abstractoperator.py", line 678, in <dictcomp>
    return {k: self.render_template(v, context, jinja_env, oids) for k, v in value.items()}
  File "/home/nicholas10/airflow/dataengvenv/lib/python3.10/site-packages/airflow/models/abstractoperator.py", line 661, in render_template
    template = jinja_env.from_string(value)
  File "/home/nicholas10/airflow/dataengvenv/lib/python3.10/site-packages/jinja2/environment.py", line 1105, in from_string
    return cls.from_code(self, self.compile(source), gs, None)
  File "/home/nicholas10/airflow/dataengvenv/lib/python3.10/site-packages/jinja2/environment.py", line 768, in compile
    self.handle_exception(source=source_hint)
  File "/home/nicholas10/airflow/dataengvenv/lib/python3.10/site-packages/jinja2/environment.py", line 936, in handle_exception
    raise rewrite_traceback_stack(source=source)
  File "<unknown>", line 1, in template
jinja2.exceptions.TemplateSyntaxError: unexpected '%'
[2023-04-29T15:34:56.954-0300] {taskinstance.py:1775} ERROR - Task failed with exception
Traceback (most recent call last):
  File "/home/nicholas10/airflow/dataengvenv/lib/python3.10/site-packages/airflow/models/taskinstance.py", line 1377, in _run_raw_task
    self._execute_task_with_callbacks(context, test_mode)
  File "/home/nicholas10/airflow/dataengvenv/lib/python3.10/site-packages/airflow/models/taskinstance.py", line 1495, in _execute_task_with_callbacks
    task_orig = self.render_templates(context=context)
  File "/home/nicholas10/airflow/dataengvenv/lib/python3.10/site-packages/airflow/models/taskinstance.py", line 2122, in render_templates
    original_task.render_template_fields(context)
  File "/home/nicholas10/airflow/dataengvenv/lib/python3.10/site-packages/airflow/models/baseoperator.py", line 1179, in render_template_fields
    self._do_render_template_fields(self, self.template_fields, context, jinja_env, set())
  File "/home/nicholas10/airflow/dataengvenv/lib/python3.10/site-packages/airflow/utils/session.py", line 75, in wrapper
    return func(*args, session=session, **kwargs)
  File "/home/nicholas10/airflow/dataengvenv/lib/python3.10/site-packages/airflow/models/abstractoperator.py", line 603, in _do_render_template_fields
    rendered_content = self.render_template(
  File "/home/nicholas10/airflow/dataengvenv/lib/python3.10/site-packages/airflow/models/abstractoperator.py", line 678, in render_template
    return {k: self.render_template(v, context, jinja_env, oids) for k, v in value.items()}
  File "/home/nicholas10/airflow/dataengvenv/lib/python3.10/site-packages/airflow/models/abstractoperator.py", line 678, in <dictcomp>
    return {k: self.render_template(v, context, jinja_env, oids) for k, v in value.items()}
  File "/home/nicholas10/airflow/dataengvenv/lib/python3.10/site-packages/airflow/models/abstractoperator.py", line 661, in render_template
    template = jinja_env.from_string(value)
  File "/home/nicholas10/airflow/dataengvenv/lib/python3.10/site-packages/jinja2/environment.py", line 1105, in from_string
    return cls.from_code(self, self.compile(source), gs, None)
  File "/home/nicholas10/airflow/dataengvenv/lib/python3.10/site-packages/jinja2/environment.py", line 768, in compile
    self.handle_exception(source=source_hint)
  File "/home/nicholas10/airflow/dataengvenv/lib/python3.10/site-packages/jinja2/environment.py", line 936, in handle_exception
    raise rewrite_traceback_stack(source=source)
  File "<unknown>", line 1, in template
jinja2.exceptions.TemplateSyntaxError: unexpected '%'
[2023-04-29T15:34:56.956-0300] {taskinstance.py:1321} INFO - Marking task as FAILED. dag_id=climate_dag, task_id=extract_data, execution_date=20230213T000000, start_date=20230429T183456, end_date=20230429T183456
[2023-04-29T15:34:56.963-0300] {standard_task_runner.py:100} ERROR - Failed to execute job 61 for task extract_data (unexpected '%'; 20584)
[2023-04-29T15:34:56.997-0300] {local_task_job.py:212} INFO - Task exited with return code 1
[2023-04-29T15:34:57.005-0300] {taskinstance.py:2585} INFO - 0 downstream tasks scheduled from follow-on schedule check
